<?xml version="1.0" encoding="utf-8"?>
<!-- This URDF was automatically created by SolidWorks to URDF Exporter! Originally created by Stephen Brawner (brawner@gmail.com) 
     Commit Version: 1.6.0-4-g7f85cfe  Build Version: 1.6.7995.38578
     For more information, please see http://wiki.ros.org/sw_urdf_exporter -->
<robot xmlns:xacro="http://www.ros.org/wiki/xacro"
  name="hexapod_modelling_team">
  <!-- Xacro defaults -->
  <xacro:property name="mesh_dir" value="package://hexapod_description/meshes"/>
  <!-- You can override e.g., ros2 run xacro xacro hexapod_modelling_team.xacro mesh_dir:=package://my_pkg/meshes -->

     <link
    name="base_link">
    <inertial>
      <origin
        xyz="-5.51899810539991E-08 -0.00018233484030792 0.0202811700296596"
        rpy="0 0 0" />
      <mass
        value="0.293447721104022" />
      <inertia
        ixx="0.000207699550833952"
        ixy="-4.2443665565616E-10"
        ixz="4.5246001720839E-11"
        iyy="0.000209742516484443"
        iyz="1.07817317605787E-06"
        izz="0.000367285854394419" />
    </inertial>
    <visual>
      <origin
        xyz="0 0 0"
        rpy="0 0 0" />
      <geometry>
        <mesh
          filename="package://hexapod_modelling_team/meshes/base_link.STL" />
      </geometry>
      <material
        name="">
        <color
          rgba="0.792156862745098 0.819607843137255 0.933333333333333 1" />
      </material>
    </visual>
    <collision>
      <origin
        xyz="0 0 0"
        rpy="0 0 0" />
      <geometry>
        <mesh
          filename="package://hexapod_modelling_team/meshes/base_link.STL" />
      </geometry>
    </collision>
  </link>
  <link
    name="Link1">
    <inertial>
      <origin
        xyz="-0.0744903369422905 0.0426388780495075 0.00559405457409265"
        rpy="0 0 0" />
      <mass
        value="0.216695042917165" />
      <inertia
        ixx="0.000130440591615854"
        ixy="5.70003393072442E-05"
        ixz="1.47989875138492E-06"
        iyy="0.000175918627847008"
        iyz="-1.28953663827065E-06"
        izz="0.000157070086725617" />
    </inertial>
    <visual>
      <origin
        xyz="0 0 0"
        rpy="0 0 0" />
      <geometry>
        <mesh
          filename="package://hexapod_modelling_team/meshes/Link1.STL" />
      </geometry>
      <material
        name="">
        <color
          rgba="0.250980392156863 0.250980392156863 0.250980392156863 1" />
      </material>
    </visual>
    <collision>
      <origin
        xyz="0 0 0"
        rpy="0 0 0" />
      <geometry>
        <mesh
          filename="package://hexapod_modelling_team/meshes/Link1.STL" />
      </geometry>
    </collision>
  </link>
  <joint
    name="rev1"
    type="continuous">
    <origin
      xyz="0 0 0.0542"
      rpy="0 0 0" />
    <parent
      link="base_link" />
    <child
      link="Link1" />
    <axis
      xyz="0 0 1" />
  </joint>
  <link
    name="Link_2">
    <inertial>
      <origin
        xyz="-0.083742489817431 0.0327173729912947 -0.00566198040215334"
        rpy="0 0 0" />
      <mass
        value="0.06148945526761" />
      <inertia
        ixx="4.23798761409314E-05"
        ixy="6.62517483598623E-05"
        ixz="-3.11291621476589E-05"
        iyy="0.000179685952658823"
        iyz="1.25707570641167E-05"
        izz="0.000201844688473023" />
    </inertial>
    <visual>
      <origin
        xyz="0 0 0"
        rpy="0 0 0" />
      <geometry>
        <mesh
          filename="package://hexapod_modelling_team/meshes/Link_2.STL" />
      </geometry>
      <material
        name="">
        <color
          rgba="0.792156862745098 0.819607843137255 0.933333333333333 1" />
      </material>
    </visual>
    <collision>
      <origin
        xyz="0 0 0"
        rpy="0 0 0" />
      <geometry>
        <mesh
          filename="package://hexapod_modelling_team/meshes/Link_2.STL" />
      </geometry>
    </collision>
  </link>
  <joint
    name="rev_2"
    type="continuous">
    <origin
      xyz="-0.079154 0.062411 0.0045"
      rpy="-1.5708 0 -0.51329" />
    <parent
      link="Link1" />
    <child
      link="Link_2" />
    <axis
      xyz="0 0 1" />
  </joint>
</robot>