<?xml version='1.0' encoding='utf-8'?>
<robot name="Volta_rev4_assembly_L_fixed.SLDASM">
  <link name="L_foot_contact" />
  <joint name="L_foot_contact_offset" type="fixed">
    <parent link="L_foot_contact" />
    <child link="L_foot" />
    <origin rpy="0 0 0" xyz="0 0 0" />
  </joint>
  <link name="L_foot">
    <inertial>
      <origin xyz="0.062345 -8.7268E-08 -0.086269" rpy="0 0 0" />
      <mass value="0.17" />
      <inertia ixx="0.0013771" ixy="1.9265E-10" ixz="0.00014937" iyy="0.0013531" iyz="-2.8031E-09" izz="0.00036097" />
    </inertial>
  </link>
  <link name="L_ankle">
    <inertial>
      <origin xyz="1.5544E-05 -0.0071279 -0.048447" rpy="0 0 0" />
      <mass value="0.387" />
      <inertia ixx="0.0002623" ixy="-8.4101E-08" ixz="-2.5171E-07" iyy="0.00027612" iyz="-5.6957E-06" izz="0.00012887" />
    </inertial>
  </link>
  <joint name="JL_ankle_r" type="continuous">
    <origin xyz="-0.094 0 0.08001" rpy="3.1416 1.5708 0" />
    <parent link="L_foot" />
    <child link="L_ankle" />
    <axis xyz="0 0 1" />
    <dynamics damping="0.5" />
  </joint>
  <link name="L_leg">
    <inertial>
      <origin xyz="-0.00033613 0.066956 -0.018284" rpy="0 0 0" />
      <mass value="0.399" />
      <inertia ixx="0.0011047" ixy="5.0372E-06" ixz="-7.0474E-10" iyy="0.00011941" iyz="-7.7939E-07" izz="0.0012018" />
    </inertial>
  </link>
  <joint name="JL_ankle_p" type="continuous">
    <origin xyz="0 0 -0.094" rpy="1.5708 -1.5708 0" />
    <parent link="L_ankle" />
    <child link="L_leg" />
    <axis xyz="0 0 1" />
    <dynamics damping="0.5" />
  </joint>
  <link name="L_thigh">
    <inertial>
      <origin xyz="-0.0652 -2.61296926088728E-05 -0.00571284504178776" rpy="0 0 0" />
      <mass value="0.434" />
      <inertia ixx="0.000133314676119059" ixy="4.76895888596183E-06" ixz="5.89592828617247E-05" iyy="0.000910595305648043" iyz="-1.08745742676649E-07" izz="0.000992151731629512" />
    </inertial>
  </link>
  <joint name="JL_knee" type="continuous">
    <origin xyz="0 0.2 0" rpy="3.1416 0 -1.5708" />
    <parent link="L_leg" />
    <child link="L_thigh" />
    <axis xyz="0 0 1" />
    <dynamics damping="0.5" />
  </joint>
  <link name="L_hip">
    <inertial>
      <origin xyz="-0.00622505417402505 1.03644355174959E-05 -0.0394687910387497" rpy="0 0 0" />
      <mass value="0.365" />
      <inertia ixx="0.000183905043741524" ixy="5.53532335974256E-09" ixz="-1.9227045011802E-05" iyy="0.000179525952112011" iyz="-8.25481863763592E-09" izz="0.000137384334109968" />
    </inertial>
  </link>
  <joint name="JL_hip_y" type="continuous">
    <origin xyz="-0.17 0 0" rpy="-1.5708 0 -1.5708" />
    <parent link="L_thigh" />
    <child link="L_hip" />
    <axis xyz="0 0 1" />
    <dynamics damping="0.5" />
  </joint>
  <link name="L_hip_connector">
    <inertial>
      <origin xyz="0.00010585 -0.0054294 -0.0079523" rpy="0 0 0" />
      <mass value="0.36" />
      <inertia ixx="0.00011402" ixy="-6.2942E-07" ixz="-4.9119E-09" iyy="7.8252E-05" iyz="1.2947E-05" izz="0.0001669" />
    </inertial>
  </link>
  <joint name="JL_hip_r" type="continuous">
    <origin xyz="0 0 -0.124" rpy="3.1416 -1.5708 3.1416" />
    <parent link="L_hip" />
    <child link="L_hip_connector" />
    <axis xyz="0 0 1" />
    <dynamics damping="0.5" />
  </joint>
  <link name="torso">
    <inertial>
      <origin xyz="-0.0240209496888825 -0.000155700444155554 -0.0670000000020784" rpy="0 0 0" />
      <mass value="1.48"/>
       <!-- <mass value="5.0" /> -->
      <inertia ixx="0.00256876355648236" ixy="-5.70226772993606E-06" ixz="6.03009601091353E-09" iyy="0.00282149878974509" iyz="7.18279243670938E-09" izz="0.00156245280350507" />
    </inertial>
  </link>
  <joint name="JL_hip_p" type="continuous">
    <origin xyz="0 -0.058 0" rpy="-1.5708 0 0" />
    <parent link="L_hip_connector" />
    <child link="torso" />
    <axis xyz="0 0 1" />
    <dynamics damping="0.5" />
  </joint>
  <link name="R_hip_connector">
    <inertial>
      <origin xyz="0.00010202 -0.0073451 0.052593" rpy="0 0 0" />
      <mass value="0.36" />
      <inertia ixx="0.00011402" ixy="-3.2815E-09" ixz="-6.3402E-07" iyy="0.0001669" iyz="1.2938E-05" izz="7.825E-05" />
    </inertial>
  </link>
  <joint name="JR_hip_p" type="continuous">
    <origin xyz="0 0 -0.134" rpy="-3.1416 0 0" />
    <parent link="torso" />
    <child link="R_hip_connector" />
    <axis xyz="0 0 1" />
    <dynamics damping="0.5" />
  </joint>
  <link name="R_hip">
    <inertial>
      <origin xyz="0.0845312089764215 1.03644159791597E-05 0.00522705416254516" rpy="0 0 0" />
      <mass value="0.365" />
      <inertia ixx="0.000137384334014772" ixy="-8.25476439029774E-09" ixz="1.9227045029606E-05" iyy="0.000179525952064276" iyz="-5.53530062553381E-09" izz="0.00018390504361425" />
    </inertial>
  </link>
  <joint name="JR_hip_r" type="continuous">
    <origin xyz="0 0 0.058" rpy="-1.5708 0 0" />
    <parent link="R_hip_connector" />
    <child link="R_hip" />
    <axis xyz="0 0 1" />
    <dynamics damping="0.5" />
  </joint>
  <link name="R_thigh">
    <inertial>
      <origin xyz="2.61220649071317E-05 -0.00571285216559152 0.104830363745175" rpy="0 0 0" />
      <mass value="0.434" />
      <inertia ixx="0.00091059588690872" ixy="1.08723678865384E-07" ixz="-4.77362261491432E-06" iyy="0.00099215239187938" iyz="5.89499891021889E-05" izz="0.000133314781951808" />
    </inertial>
  </link>
  <joint name="JR_hip_y" type="continuous">
    <origin xyz="0.124 0 0" rpy="0 1.5708 0" />
    <parent link="R_hip" />
    <child link="R_thigh" />
    <axis xyz="0 0 1" />
    <dynamics damping="0.5" />
  </joint>
  <link name="R_leg">
    <inertial>
      <origin xyz="0.133043649308305 -6.32267831356115E-06 0.0122842332525925" rpy="0 0 0" />
      <mass value="0.399" />
      <inertia ixx="0.000119385625520499" ixy="-2.44371178214403E-09" ixz="-7.79379986156302E-07" iyy="0.00110476919106434" iyz="-4.6909469672429E-09" izz="0.00120175070200165" />
    </inertial>
  </link>
  <joint name="JR_knee" type="continuous">
    <origin xyz="0 0 0.17" rpy="1.5708 -1.5708 -3.1416" />
    <parent link="R_thigh" />
    <child link="R_leg" />
    <axis xyz="0 0 1" />
    <dynamics damping="0.5" />
  </joint>
  <link name="R_ankle">
    <inertial>
      <origin xyz="0.045553 -1.5544E-05 0.0011279" rpy="0 0 0" />
      <mass value="0.387" />
      <inertia ixx="0.00012887" ixy="2.5171E-07" ixz="5.6957E-06" iyy="0.0002623" iyz="-8.4101E-08" izz="0.00027612" />
    </inertial>
  </link>
  <joint name="JR_ankle_p" type="continuous">
    <origin xyz="0.2 0 0" rpy="-3.1416 0 1.5708" />
    <parent link="R_leg" />
    <child link="R_ankle" />
    <axis xyz="0 0 1" />
    <dynamics damping="0.5" />
  </joint>
  <link name="R_foot">
    <inertial>
      <origin xyz="0.0623449009659792 -8.64917147347377E-08 -0.0862689735387264" rpy="0 0 0" />
      <mass value="0.17" />
      <inertia ixx="0.00137707296671824" ixy="1.94158159555216E-10" ixz="0.000149371366026613" iyy="0.00135311437864457" iyz="-2.81247052416592E-09" izz="0.000360973079568637" />
    </inertial>
  </link>
  <joint name="JR_ankle_r" type="continuous">
    <origin xyz="0.094 0 0" rpy="1.5708 0 1.5708" />
    <parent link="R_ankle" />
    <child link="R_foot" />
    <axis xyz="0 0 1" />
    <dynamics damping="0.5" />
  </joint>

  <transmission name="trans_JL_ankle_r" type="SimpleTransmission">
    <actuator name="JL_ankle_r_motor">
      <mechanicalReduction>1.0</mechanicalReduction>
    </actuator>
    <joint name="JL_ankle_r" />
  </transmission>
  <transmission name="trans_JL_ankle_p" type="SimpleTransmission">
    <actuator name="JL_ankle_p_motor">
      <mechanicalReduction>1.0</mechanicalReduction>
    </actuator>
    <joint name="JL_ankle_p" />
  </transmission>
  <transmission name="trans_JL_knee" type="SimpleTransmission">
    <actuator name="JL_knee_motor">
      <mechanicalReduction>1.0</mechanicalReduction>
    </actuator>
    <joint name="JL_knee" />
  </transmission>
  <transmission name="trans_JL_hip_y" type="SimpleTransmission">
    <actuator name="JL_hip_y_motor">
      <mechanicalReduction>1.0</mechanicalReduction>
    </actuator>
    <joint name="JL_hip_y" />
  </transmission>
  <transmission name="trans_JL_hip_r" type="SimpleTransmission">
    <actuator name="JL_hip_r_motor">
      <mechanicalReduction>1.0</mechanicalReduction>
    </actuator>
    <joint name="JL_hip_r" />
  </transmission>
  <transmission name="trans_JL_hip_p" type="SimpleTransmission">
    <actuator name="JL_hip_p_motor">
      <mechanicalReduction>1.0</mechanicalReduction>
    </actuator>
    <joint name="JL_hip_p" />
  </transmission>
  <transmission name="trans_JR_hip_p" type="SimpleTransmission">
    <actuator name="JR_hip_p_motor">
      <mechanicalReduction>1.0</mechanicalReduction>
    </actuator>
    <joint name="JR_hip_p" />
  </transmission>
  <transmission name="trans_JR_hip_r" type="SimpleTransmission">
    <actuator name="JR_hip_r_motor">
      <mechanicalReduction>1.0</mechanicalReduction>
    </actuator>
    <joint name="JR_hip_r" />
  </transmission>
  <transmission name="trans_JR_hip_y" type="SimpleTransmission">
    <actuator name="JR_hip_y_motor">
      <mechanicalReduction>1.0</mechanicalReduction>
    </actuator>
    <joint name="JR_hip_y" />
  </transmission>
  <transmission name="trans_JR_knee" type="SimpleTransmission">
    <actuator name="JR_knee_motor">
      <mechanicalReduction>1.0</mechanicalReduction>
    </actuator>
    <joint name="JR_knee" />
  </transmission>
  <transmission name="trans_JR_ankle_p" type="SimpleTransmission">
    <actuator name="JR_ankle_p_motor">
      <mechanicalReduction>1.0</mechanicalReduction>
    </actuator>
    <joint name="JR_ankle_p" />
  </transmission>
  <transmission name="trans_JR_ankle_r" type="SimpleTransmission">
    <actuator name="JR_ankle_r_motor">
      <mechanicalReduction>1.0</mechanicalReduction>
    </actuator>
    <joint name="JR_ankle_r" />
  </transmission>
</robot>