<?xml version='1.0' encoding='utf-8'?>
<robot name="Volta_rev4_assembly_L_fixed.SLDASM">
  <link name="L_foot_contact" />
  <joint name="L_foot_contact_offset" type="fixed">
    <parent link="L_foot_contact" />
    <child link="L_foot" />
    <origin rpy="0 0 0" xyz="0 0 0" />

  </joint>
  <link name="L_foot">
    <inertial>
      <origin xyz="0.062345 -8.7268E-08 -0.086269" rpy="0 0 0" />
      <mass value="0.17" />
      <inertia ixx="0.0013771" ixy="1.9265E-10" ixz="0.00014937" iyy="0.0013531" iyz="-2.8031E-09" izz="0.00036097" />
    </inertial>
  </link>
  <link name="L_ankle">
    <inertial>
      <origin xyz="1.5544E-05 -0.0071279 -0.048447" rpy="0 0 0" />
      <mass value="0.387" />
      <inertia ixx="0.0002623" ixy="-8.4101E-08" ixz="-2.5171E-07" iyy="0.00027612" iyz="-5.6957E-06" izz="0.00012887" />
    </inertial>
  </link>
  <joint name="JL_ankle_r" type="continuous">
    <origin xyz="-0.094 0 0.08001" rpy="3.1416 1.5708 0" />
    <parent link="L_foot" />
    <child link="L_ankle" />
    <axis xyz="0 0 1" />
    <dynamics damping="0.5" />
  </joint>
  <link name="L_leg">
    <inertial>
      <origin xyz="-0.00033613 0.066956 -0.018284" rpy="0 0 0" />
      <mass value="0.399" />
      <inertia ixx="0.0011047" ixy="5.0372E-06" ixz="-7.0474E-10" iyy="0.00011941" iyz="-7.7939E-07" izz="0.0012018" />
    </inertial>
  </link>
  <joint name="JL_ankle_p" type="continuous">
    <origin xyz="0 0 -0.094" rpy="1.5708 -1.5708 0" />
    <parent link="L_ankle" />
    <child link="L_leg" />
    <axis xyz="0 0 1" />
    <dynamics damping="0.5" />
  </joint>
  <link name="L_thigh">
    <inertial>
      <origin xyz="-0.0652 -2.61296926088728E-05 -0.00571284504178776" rpy="0 0 0" />
      <mass value="0.434" />
      <inertia ixx="0.000133314676119059" ixy="4.76895888596183E-06" ixz="5.89592828617247E-05" iyy="0.000910595305648043" iyz="-1.08745742676649E-07" izz="0.000992151731629512" />
    </inertial>
  </link>
  <joint name="JL_knee" type="continuous">
    <origin xyz="0 0.2 0" rpy="3.1416 0 -1.5708" />
    <parent link="L_leg" />
    <child link="L_thigh" />
    <axis xyz="0 0 1" />
    <dynamics damping="0.5" />
  </joint>
  <link name="L_hip">
    <inertial>
      <origin xyz="-0.00622505417402505 1.03644355174959E-05 -0.0394687910387497" rpy="0 0 0" />
      <mass value="0.365" />
      <!-- <mass value="1.25" /> -->
      <inertia ixx="0.000183905043741524" ixy="5.53532335974256E-09" ixz="-1.9227045011802E-05" iyy="0.000179525952112011" iyz="-8.25481863763592E-09" izz="0.000137384334109968" />
    </inertial>
  </link>
  <joint name="JL_hip_y" type="continuous">
    <origin xyz="-0.17 0 0" rpy="-1.5708 0 -1.5708" />
    <parent link="L_thigh" />
    <child link="L_hip" />
    <axis xyz="0 0 1" />
    <dynamics damping="0.5" />
  </joint>
  <link name="L_hip_connector">
    <inertial>
      <origin xyz="0.00010585 -0.0054294 -0.0079523" rpy="0 0 0" />
      <mass value="0.36" />
      <!-- <mass value="0.8" /> -->
      <inertia ixx="0.00011402" ixy="-6.2942E-07" ixz="-4.9119E-09" iyy="7.8252E-05" iyz="1.2947E-05" izz="0.0001669" />
    </inertial>
  </link>
  <joint name="JL_hip_r" type="continuous">
    <origin xyz="0 0 -0.124" rpy="3.1416 -1.5708 3.1416" />
    <parent link="L_hip" />
    <child link="L_hip_connector" />
    <axis xyz="0 0 1" />
    <dynamics damping="0.5" />
  </joint>
  <link name="torso">
    <inertial>
      <origin xyz="-0.0240209496888825 -0.000155700444155554 -0.0670000000020784" rpy="0 0 0" />
      <mass value="0.72" /> 
      <!-- <mass value="2.5" />  -->
      <inertia ixx="0.00256876355648236" ixy="-5.70226772993606E-06" ixz="6.03009601091353E-09" iyy="0.00282149878974509" iyz="7.18279243670938E-09" izz="0.00156245280350507" />
    </inertial>
  </link>
  <joint name="JL_hip_p" type="continuous">
    <origin xyz="0 -0.058 0" rpy="-1.5708 0 0" />
    <parent link="L_hip_connector" />
    <child link="torso" />
    <axis xyz="0 0 1" />
    <dynamics damping="0.5" />
  </joint>

  <transmission name="trans_JL_ankle_r" type="SimpleTransmission">
    <actuator name="JL_ankle_r_motor">
      <mechanicalReduction>1.0</mechanicalReduction>
    </actuator>
    <joint name="JL_ankle_r" />
  </transmission>
  <transmission name="trans_JL_ankle_p" type="SimpleTransmission">
    <actuator name="JL_ankle_p_motor">
      <mechanicalReduction>1.0</mechanicalReduction>
    </actuator>
    <joint name="JL_ankle_p" />
  </transmission>
  <transmission name="trans_JL_knee" type="SimpleTransmission">
    <actuator name="JL_knee_motor">
      <mechanicalReduction>1.0</mechanicalReduction>
    </actuator>
    <joint name="JL_knee" />
  </transmission>
  <transmission name="trans_JL_hip_y" type="SimpleTransmission">
    <actuator name="JL_hip_y_motor">
      <mechanicalReduction>1.0</mechanicalReduction>
    </actuator>
    <joint name="JL_hip_y" />
  </transmission>
  <transmission name="trans_JL_hip_r" type="SimpleTransmission">
    <actuator name="JL_hip_r_motor">
      <mechanicalReduction>1.0</mechanicalReduction>
    </actuator>
    <joint name="JL_hip_r" />
  </transmission>
  <transmission name="trans_JL_hip_p" type="SimpleTransmission">
    <actuator name="JL_hip_p_motor">
      <mechanicalReduction>1.0</mechanicalReduction>
    </actuator>
    <joint name="JL_hip_p" />
  </transmission>
</robot>